<?xml version='1.0'?>
<sdf version='1.6'>
  <model name='bag'>
   

    <link name='base_link'>    
      
      <visual name='base_link_visual'>
        <pose frame=''>0 0 0 0 -0 0</pose>
        <geometry>
          <sphere>
            <radius>0.03</radius>
          </sphere>
        </geometry>
      </visual>

    </link>

    <joint name="base_link_joint" type="fixed">
      <parent>world</parent>
      <child>base_link</child>
      <pose>0 0 2.0 0 0 0</pose>
    </joint>

    <joint name="bag_joint" type="ball">
      <parent>base_link</parent>
      <child>bag_link</child>
      <pose>0 0 0 0 0 0</pose>
    </joint>


    <link name='bag_link'>    
      <visual name='bag_link_visual'>
        <pose frame=''>0 0 0 0 -0 0</pose>
        <geometry>
          <mesh>
            <uri>model://bag/meshes/bag.dae</uri>
            <scale>1.0 1.0 1.0</scale>
          </mesh>
        </geometry>
      </visual>
      <collision name='bag_link_collision'>
        <pose frame=''>0 0 0 0 -0 0</pose>
        <geometry>
          <mesh>
            <uri>model://bag/meshes/bag.stl</uri>
            <scale>1.0 1.0 1.0</scale>
          </mesh>
        </geometry>
     </collision>
     <inertial>
          <pose frame=''>0 0 -2.0 0 0 0</pose>
          <mass>10.0</mass>
          <inertia>
            <ixx>3.9583333333333335</ixx>
            <ixy>0.000000</ixy>
            <ixz>0.000000</ixz>
            <iyy>3.9583333333333335</iyy>
            <iyz>0.000000</iyz>
            <izz>1.25</izz>
          </inertia>
      </inertial>
    </link>



    <static>0</static>
    <allow_auto_disable>1</allow_auto_disable>

  </model>
</sdf>