<?xml version="1.0" ?>
<sdf version="1.5">
  <model name="jibo">

    <link name="base_link">
      <pose>0 0 0 0 0 0</pose>
      <inertial>
        <inertia>
          <ixx>0.002025</ixx>
          <ixy>0</ixy>
          <ixz>0</ixz>
          <iyy>0.002025</iyy>
          <iyz>0</iyz>
          <izz>0.0016</izz>
        </inertia>
        <mass>0.5</mass>
      </inertial>
      <collision name="collision">
        <pose>0 0 0 0 0 0</pose>
        <geometry>
          <cylinder>
            <radius>0.08</radius>
            <length>0.012</length>
          </cylinder>
        </geometry>
        <surface>
          <friction>
            <ode>
              <mu>10</mu>
              <mu2>10</mu2>
              <fdir1>0 0 0</fdir1>
              <slip1>0</slip1>
              <slip2>0</slip2>
            </ode>
          </friction>
        </surface>
      </collision>
      <visual name="visual">
        <pose>0 0 0 0 0 0</pose>
        <geometry>
          <mesh>
            <uri>model://jibo/meshes/jibo_final_parts_base.dae</uri>
          </mesh>
        </geometry>
      </visual>
    </link>



    <link name="waist_link">
      <pose>0 0 0 0 0 0</pose>
      <inertial>
        <inertia>
          <ixx>0.0011625</ixx>
          <ixy>0</ixy>
          <ixz>0</ixz>
          <iyy>0.0011625</iyy>
          <iyz>0</iyz>
          <izz>0.002025</izz>
        </inertia>
        <mass>0.5</mass>
      </inertial>
      <collision name="collision">
        <pose>0 0 0 0 0 0</pose>
        <geometry>
          <cylinder>
            <radius>0.09</radius>
            <length>0.06</length>
          </cylinder>
        </geometry>
        <surface>
          <friction>
            <ode>
              <mu>10</mu>
              <mu2>10</mu2>
              <fdir1>0 0 0</fdir1>
              <slip1>0</slip1>
              <slip2>0</slip2>
            </ode>
          </friction>
        </surface>
      </collision>
      <visual name="visual">
        <pose>0 0 0 0 0 0</pose>
        <geometry>
          <mesh>
            <uri>model://jibo/meshes/jibo_final_parts_waist.dae</uri>
          </mesh>
        </geometry>
      </visual>
    </link>

    <!--
    <link name="body_link">
      <pose>0 0 0 0 0 0</pose>
      <inertial>
        <inertia>
          <ixx>0.00166354166667</ixx>
          <ixy>0</ixy>
          <ixz>0</ixz>
          <iyy>0.00166354166667</iyy>
          <iyz>0</iyz>
          <izz>0.002025</izz>
        </inertia>
        <mass>0.5</mass>
      </inertial>
      <collision name="collision">
        <pose>0 0 0 0 0 0</pose>
        <geometry>
          <cylinder>
            <radius>0.09</radius>
            <length>0.125</length>
          </cylinder>
        </geometry>
        <surface>
          <friction>
            <ode>
              <mu>10</mu>
              <mu2>10</mu2>
              <fdir1>0 0 0</fdir1>
              <slip1>0</slip1>
              <slip2>0</slip2>
            </ode>
          </friction>
        </surface>
      </collision>
      <visual name="visual">
        <pose>0 0 0 0 0 0</pose>
        <geometry>
          <mesh>
            <uri>model://jibo/meshes/jibo_final_parts_body.dae</uri>
          </mesh>
        </geometry>
      </visual>
    </link>


    <link name="head_link">
      <pose>0 0 0 0 0 0</pose>
      <inertial>
        <inertia>
          <ixx>0.8</ixx>
          <ixy>0</ixy>
          <ixz>0</ixz>
          <iyy>0.8</iyy>
          <iyz>0</iyz>
          <izz>0.8</izz>
        </inertia>
        <mass>0.5</mass>
      </inertial>
      <collision name="collision">
        <pose>0 0 0 0 0 0</pose>
        <geometry>
          <sphere>
            <radius>0.125</radius>
          </sphere>
        </geometry>
        <surface>
          <friction>
            <ode>
              <mu>10</mu>
              <mu2>10</mu2>
              <fdir1>0 0 0</fdir1>
              <slip1>0</slip1>
              <slip2>0</slip2>
            </ode>
          </friction>
        </surface>
      </collision>
      <visual name="visual">
        <pose>0 0 0 0 0 0</pose>
        <geometry>
          <mesh>
            <uri>model://jibo/meshes/jibo_final_parts_head.dae</uri>
          </mesh>
        </geometry>
      </visual>
    </link>
    -->

    <joint name="base_waist_link" type="revolute">
      <parent>base_link</parent>
      <child>waist_link</child>
      <axis>
        <xyz>0 0 1</xyz>
        <use_parent_model_frame>true</use_parent_model_frame>
      </axis>
    </joint>


  </model>
</sdf>
